INFO 2025-06-17 17:40:44,365 autoreload 1396 23112 Watching for file changes with StatReloader
INFO 2025-06-17 17:41:41,684 autoreload 21380 24444 Watching for file changes with StatReloader
INFO 2025-06-17 17:44:01,581 autoreload 21380 24444 D:\zpj\python\ArtiOps\backend\config\settings.py changed, reloading.
INFO 2025-06-17 17:44:03,244 autoreload 27760 4512 Watching for file changes with StatReloader
INFO 2025-06-17 17:45:00,417 autoreload 27760 4512 D:\zpj\python\ArtiOps\backend\config\settings.py changed, reloading.
INFO 2025-06-17 17:45:01,708 autoreload 18908 19348 Watching for file changes with StatReloader
INFO 2025-06-17 17:45:15,630 autoreload 26144 7644 Watching for file changes with StatReloader
INFO 2025-06-17 17:50:04,102 autoreload 26144 7644 D:\zpj\python\ArtiOps\backend\config\settings.py changed, reloading.
INFO 2025-06-17 17:50:05,797 autoreload 6256 15592 Watching for file changes with StatReloader
INFO 2025-06-17 17:52:12,751 autoreload 22396 26156 Watching for file changes with StatReloader
INFO 2025-06-17 17:52:52,173 basehttp 22396 25384 "GET /admin/ HTTP/1.1" 302 0
INFO 2025-06-17 17:52:52,210 basehttp 22396 25384 "GET /admin/login/?next=/admin/ HTTP/1.1" 200 4195
INFO 2025-06-17 17:52:52,533 basehttp 22396 30356 "GET /static/admin/css/dark_mode.css HTTP/1.1" 200 2929
INFO 2025-06-17 17:52:52,539 basehttp 22396 25384 "GET /static/admin/css/base.css HTTP/1.1" 200 21207
INFO 2025-06-17 17:52:52,561 basehttp 22396 27476 "GET /static/admin/css/nav_sidebar.css HTTP/1.1" 200 2694
INFO 2025-06-17 17:52:52,563 basehttp 22396 25384 "GET /static/admin/js/nav_sidebar.js HTTP/1.1" 200 3063
INFO 2025-06-17 17:52:52,563 basehttp 22396 27476 "GET /static/admin/js/theme.js HTTP/1.1" 200 1943
INFO 2025-06-17 17:52:52,581 basehttp 22396 25492 "GET /static/admin/css/login.css HTTP/1.1" 200 958
INFO 2025-06-17 17:52:52,581 basehttp 22396 29324 "GET /static/admin/css/responsive.css HTTP/1.1" 200 18557
WARNING 2025-06-17 17:52:52,650 log 22396 29324 Not Found: /favicon.ico
WARNING 2025-06-17 17:52:52,651 basehttp 22396 29324 "GET /favicon.ico HTTP/1.1" 404 2604
ERROR 2025-06-17 17:53:48,883 log 22396 29324 Internal Server Error: /admin/login/
Traceback (most recent call last):
  File "D:\zpj\python\ArtiOps\backend\venv\Lib\site-packages\django\db\backends\utils.py", line 89, in _execute
    return self.cursor.execute(sql, params)
           ^^^^^^^^^^^^^^^^^^^^^^^^^^^^^^^^
  File "D:\zpj\python\ArtiOps\backend\venv\Lib\site-packages\django\db\backends\sqlite3\base.py", line 328, in execute
    return super().execute(query, params)
           ^^^^^^^^^^^^^^^^^^^^^^^^^^^^^^
sqlite3.OperationalError: no such table: users_user

The above exception was the direct cause of the following exception:

Traceback (most recent call last):
  File "D:\zpj\python\ArtiOps\backend\venv\Lib\site-packages\django\core\handlers\exception.py", line 55, in inner
    response = get_response(request)
               ^^^^^^^^^^^^^^^^^^^^^
  File "D:\zpj\python\ArtiOps\backend\venv\Lib\site-packages\django\core\handlers\base.py", line 197, in _get_response
    response = wrapped_callback(request, *callback_args, **callback_kwargs)
               ^^^^^^^^^^^^^^^^^^^^^^^^^^^^^^^^^^^^^^^^^^^^^^^^^^^^^^^^^^^^
  File "D:\zpj\python\ArtiOps\backend\venv\Lib\site-packages\django\utils\decorators.py", line 46, in _wrapper
    return bound_method(*args, **kwargs)
           ^^^^^^^^^^^^^^^^^^^^^^^^^^^^^
  File "D:\zpj\python\ArtiOps\backend\venv\Lib\site-packages\django\views\decorators\cache.py", line 62, in _wrapper_view_func
    response = view_func(request, *args, **kwargs)
               ^^^^^^^^^^^^^^^^^^^^^^^^^^^^^^^^^^^
  File "D:\zpj\python\ArtiOps\backend\venv\Lib\site-packages\django\contrib\admin\sites.py", line 441, in login
    return LoginView.as_view(**defaults)(request)
           ^^^^^^^^^^^^^^^^^^^^^^^^^^^^^^^^^^^^^^
  File "D:\zpj\python\ArtiOps\backend\venv\Lib\site-packages\django\views\generic\base.py", line 104, in view
    return self.dispatch(request, *args, **kwargs)
           ^^^^^^^^^^^^^^^^^^^^^^^^^^^^^^^^^^^^^^^
  File "D:\zpj\python\ArtiOps\backend\venv\Lib\site-packages\django\utils\decorators.py", line 46, in _wrapper
    return bound_method(*args, **kwargs)
           ^^^^^^^^^^^^^^^^^^^^^^^^^^^^^
  File "D:\zpj\python\ArtiOps\backend\venv\Lib\site-packages\django\views\decorators\debug.py", line 92, in sensitive_post_parameters_wrapper
    return view(request, *args, **kwargs)
           ^^^^^^^^^^^^^^^^^^^^^^^^^^^^^^
  File "D:\zpj\python\ArtiOps\backend\venv\Lib\site-packages\django\utils\decorators.py", line 46, in _wrapper
    return bound_method(*args, **kwargs)
           ^^^^^^^^^^^^^^^^^^^^^^^^^^^^^
  File "D:\zpj\python\ArtiOps\backend\venv\Lib\site-packages\django\utils\decorators.py", line 134, in _wrapper_view
    response = view_func(request, *args, **kwargs)
               ^^^^^^^^^^^^^^^^^^^^^^^^^^^^^^^^^^^
  File "D:\zpj\python\ArtiOps\backend\venv\Lib\site-packages\django\utils\decorators.py", line 46, in _wrapper
    return bound_method(*args, **kwargs)
           ^^^^^^^^^^^^^^^^^^^^^^^^^^^^^
  File "D:\zpj\python\ArtiOps\backend\venv\Lib\site-packages\django\views\decorators\cache.py", line 62, in _wrapper_view_func
    response = view_func(request, *args, **kwargs)
               ^^^^^^^^^^^^^^^^^^^^^^^^^^^^^^^^^^^
  File "D:\zpj\python\ArtiOps\backend\venv\Lib\site-packages\django\contrib\auth\views.py", line 90, in dispatch
    return super().dispatch(request, *args, **kwargs)
           ^^^^^^^^^^^^^^^^^^^^^^^^^^^^^^^^^^^^^^^^^^
  File "D:\zpj\python\ArtiOps\backend\venv\Lib\site-packages\django\views\generic\base.py", line 143, in dispatch
    return handler(request, *args, **kwargs)
           ^^^^^^^^^^^^^^^^^^^^^^^^^^^^^^^^^
  File "D:\zpj\python\ArtiOps\backend\venv\Lib\site-packages\django\views\generic\edit.py", line 152, in post
    if form.is_valid():
       ^^^^^^^^^^^^^^^
  File "D:\zpj\python\ArtiOps\backend\venv\Lib\site-packages\django\forms\forms.py", line 201, in is_valid
    return self.is_bound and not self.errors
                                 ^^^^^^^^^^^
  File "D:\zpj\python\ArtiOps\backend\venv\Lib\site-packages\django\forms\forms.py", line 196, in errors
    self.full_clean()
  File "D:\zpj\python\ArtiOps\backend\venv\Lib\site-packages\django\forms\forms.py", line 434, in full_clean
    self._clean_form()
  File "D:\zpj\python\ArtiOps\backend\venv\Lib\site-packages\django\forms\forms.py", line 455, in _clean_form
    cleaned_data = self.clean()
                   ^^^^^^^^^^^^
  File "D:\zpj\python\ArtiOps\backend\venv\Lib\site-packages\django\contrib\auth\forms.py", line 242, in clean
    self.user_cache = authenticate(
                      ^^^^^^^^^^^^^
  File "D:\zpj\python\ArtiOps\backend\venv\Lib\site-packages\django\views\decorators\debug.py", line 42, in sensitive_variables_wrapper
    return func(*func_args, **func_kwargs)
           ^^^^^^^^^^^^^^^^^^^^^^^^^^^^^^^
  File "D:\zpj\python\ArtiOps\backend\venv\Lib\site-packages\django\contrib\auth\__init__.py", line 77, in authenticate
    user = backend.authenticate(request, **credentials)
           ^^^^^^^^^^^^^^^^^^^^^^^^^^^^^^^^^^^^^^^^^^^^
  File "D:\zpj\python\ArtiOps\backend\venv\Lib\site-packages\django\contrib\auth\backends.py", line 46, in authenticate
    user = UserModel._default_manager.get_by_natural_key(username)
           ^^^^^^^^^^^^^^^^^^^^^^^^^^^^^^^^^^^^^^^^^^^^^^^^^^^^^^^
  File "D:\zpj\python\ArtiOps\backend\venv\Lib\site-packages\django\contrib\auth\base_user.py", line 54, in get_by_natural_key
    return self.get(**{self.model.USERNAME_FIELD: username})
           ^^^^^^^^^^^^^^^^^^^^^^^^^^^^^^^^^^^^^^^^^^^^^^^^^
  File "D:\zpj\python\ArtiOps\backend\venv\Lib\site-packages\django\db\models\manager.py", line 87, in manager_method
    return getattr(self.get_queryset(), name)(*args, **kwargs)
           ^^^^^^^^^^^^^^^^^^^^^^^^^^^^^^^^^^^^^^^^^^^^^^^^^^^
  File "D:\zpj\python\ArtiOps\backend\venv\Lib\site-packages\django\db\models\query.py", line 633, in get
    num = len(clone)
          ^^^^^^^^^^
  File "D:\zpj\python\ArtiOps\backend\venv\Lib\site-packages\django\db\models\query.py", line 380, in __len__
    self._fetch_all()
  File "D:\zpj\python\ArtiOps\backend\venv\Lib\site-packages\django\db\models\query.py", line 1881, in _fetch_all
    self._result_cache = list(self._iterable_class(self))
                         ^^^^^^^^^^^^^^^^^^^^^^^^^^^^^^^^
  File "D:\zpj\python\ArtiOps\backend\venv\Lib\site-packages\django\db\models\query.py", line 91, in __iter__
    results = compiler.execute_sql(
              ^^^^^^^^^^^^^^^^^^^^^
  File "D:\zpj\python\ArtiOps\backend\venv\Lib\site-packages\django\db\models\sql\compiler.py", line 1560, in execute_sql
    cursor.execute(sql, params)
  File "D:\zpj\python\ArtiOps\backend\venv\Lib\site-packages\django\db\backends\utils.py", line 102, in execute
    return super().execute(sql, params)
           ^^^^^^^^^^^^^^^^^^^^^^^^^^^^
  File "D:\zpj\python\ArtiOps\backend\venv\Lib\site-packages\django\db\backends\utils.py", line 67, in execute
    return self._execute_with_wrappers(
           ^^^^^^^^^^^^^^^^^^^^^^^^^^^^
  File "D:\zpj\python\ArtiOps\backend\venv\Lib\site-packages\django\db\backends\utils.py", line 80, in _execute_with_wrappers
    return executor(sql, params, many, context)
           ^^^^^^^^^^^^^^^^^^^^^^^^^^^^^^^^^^^^
  File "D:\zpj\python\ArtiOps\backend\venv\Lib\site-packages\django\db\backends\utils.py", line 84, in _execute
    with self.db.wrap_database_errors:
  File "D:\zpj\python\ArtiOps\backend\venv\Lib\site-packages\django\db\utils.py", line 91, in __exit__
    raise dj_exc_value.with_traceback(traceback) from exc_value
  File "D:\zpj\python\ArtiOps\backend\venv\Lib\site-packages\django\db\backends\utils.py", line 89, in _execute
    return self.cursor.execute(sql, params)
           ^^^^^^^^^^^^^^^^^^^^^^^^^^^^^^^^
  File "D:\zpj\python\ArtiOps\backend\venv\Lib\site-packages\django\db\backends\sqlite3\base.py", line 328, in execute
    return super().execute(query, params)
           ^^^^^^^^^^^^^^^^^^^^^^^^^^^^^^
django.db.utils.OperationalError: no such table: users_user
ERROR 2025-06-17 17:53:48,891 basehttp 22396 29324 "POST /admin/login/?next=/admin/ HTTP/1.1" 500 254695
INFO 2025-06-17 17:54:14,709 basehttp 22396 29324 "GET /admin/login/?next=/admin/ HTTP/1.1" 200 4195
INFO 2025-06-17 17:56:19,710 autoreload 22396 26156 D:\zpj\python\ArtiOps\backend\apps\builds\models.py changed, reloading.
INFO 2025-06-17 17:56:21,478 autoreload 25088 17744 Watching for file changes with StatReloader
INFO 2025-06-17 17:56:39,080 autoreload 25088 17744 D:\zpj\python\ArtiOps\backend\apps\builds\serializers.py changed, reloading.
INFO 2025-06-17 17:56:40,850 autoreload 17968 12156 Watching for file changes with StatReloader
INFO 2025-06-17 17:56:58,479 autoreload 17968 12156 D:\zpj\python\ArtiOps\backend\apps\credentials\models.py changed, reloading.
INFO 2025-06-17 17:57:00,411 autoreload 20476 21964 Watching for file changes with StatReloader
INFO 2025-06-17 17:57:17,173 autoreload 20476 21964 D:\zpj\python\ArtiOps\backend\apps\credentials\serializers.py changed, reloading.
INFO 2025-06-17 17:57:19,025 autoreload 29964 25944 Watching for file changes with StatReloader
INFO 2025-06-17 17:57:36,520 autoreload 29964 25944 D:\zpj\python\ArtiOps\backend\apps\logs\models.py changed, reloading.
INFO 2025-06-17 17:57:38,008 autoreload 23200 832 Watching for file changes with StatReloader
INFO 2025-06-17 17:58:06,987 autoreload 23200 832 D:\zpj\python\ArtiOps\backend\apps\logs\middleware.py changed, reloading.
INFO 2025-06-17 17:58:08,914 autoreload 2444 17964 Watching for file changes with StatReloader
INFO 2025-06-17 17:58:18,750 autoreload 2444 17964 D:\zpj\python\ArtiOps\backend\apps\logs\middleware.py changed, reloading.
INFO 2025-06-17 17:58:20,576 autoreload 27868 14468 Watching for file changes with StatReloader
INFO 2025-06-17 17:58:31,364 autoreload 27868 14468 D:\zpj\python\ArtiOps\backend\apps\logs\middleware.py changed, reloading.
INFO 2025-06-17 17:58:33,372 autoreload 17328 11004 Watching for file changes with StatReloader
INFO 2025-06-17 17:59:52,595 autoreload 29188 25716 Watching for file changes with StatReloader
INFO 2025-06-17 18:00:31,118 basehttp 29188 1612 "GET /admin/ HTTP/1.1" 302 0
INFO 2025-06-17 18:00:31,154 basehttp 29188 1612 "GET /admin/login/?next=/admin/ HTTP/1.1" 200 4195
INFO 2025-06-17 18:00:31,177 basehttp 29188 1612 "GET /static/admin/css/base.css HTTP/1.1" 304 0
INFO 2025-06-17 18:00:31,182 basehttp 29188 1612 "GET /static/admin/css/dark_mode.css HTTP/1.1" 304 0
INFO 2025-06-17 18:00:31,182 basehttp 29188 18132 "GET /static/admin/css/nav_sidebar.css HTTP/1.1" 304 0
INFO 2025-06-17 18:00:31,227 basehttp 29188 18132 "GET /static/admin/css/login.css HTTP/1.1" 304 0
INFO 2025-06-17 18:00:31,229 basehttp 29188 1612 "GET /static/admin/css/responsive.css HTTP/1.1" 304 0
INFO 2025-06-17 18:00:31,230 basehttp 29188 4892 "GET /static/admin/js/theme.js HTTP/1.1" 304 0
INFO 2025-06-17 18:00:31,233 basehttp 29188 4892 "GET /static/admin/js/nav_sidebar.js HTTP/1.1" 304 0
INFO 2025-06-17 18:01:42,918 autoreload 10840 15072 Watching for file changes with StatReloader
ERROR 2025-06-17 18:02:11,442 log 10840 17456 Internal Server Error: /admin/login/
Traceback (most recent call last):
  File "D:\zpj\python\ArtiOps\backend\venv\Lib\site-packages\django\db\backends\utils.py", line 89, in _execute
    return self.cursor.execute(sql, params)
           ^^^^^^^^^^^^^^^^^^^^^^^^^^^^^^^^
  File "D:\zpj\python\ArtiOps\backend\venv\Lib\site-packages\django\db\backends\sqlite3\base.py", line 328, in execute
    return super().execute(query, params)
           ^^^^^^^^^^^^^^^^^^^^^^^^^^^^^^
sqlite3.OperationalError: no such table: users_user

The above exception was the direct cause of the following exception:

Traceback (most recent call last):
  File "D:\zpj\python\ArtiOps\backend\venv\Lib\site-packages\django\core\handlers\exception.py", line 55, in inner
    response = get_response(request)
               ^^^^^^^^^^^^^^^^^^^^^
  File "D:\zpj\python\ArtiOps\backend\venv\Lib\site-packages\django\core\handlers\base.py", line 197, in _get_response
    response = wrapped_callback(request, *callback_args, **callback_kwargs)
               ^^^^^^^^^^^^^^^^^^^^^^^^^^^^^^^^^^^^^^^^^^^^^^^^^^^^^^^^^^^^
  File "D:\zpj\python\ArtiOps\backend\venv\Lib\site-packages\django\utils\decorators.py", line 46, in _wrapper
    return bound_method(*args, **kwargs)
           ^^^^^^^^^^^^^^^^^^^^^^^^^^^^^
  File "D:\zpj\python\ArtiOps\backend\venv\Lib\site-packages\django\views\decorators\cache.py", line 62, in _wrapper_view_func
    response = view_func(request, *args, **kwargs)
               ^^^^^^^^^^^^^^^^^^^^^^^^^^^^^^^^^^^
  File "D:\zpj\python\ArtiOps\backend\venv\Lib\site-packages\django\contrib\admin\sites.py", line 441, in login
    return LoginView.as_view(**defaults)(request)
           ^^^^^^^^^^^^^^^^^^^^^^^^^^^^^^^^^^^^^^
  File "D:\zpj\python\ArtiOps\backend\venv\Lib\site-packages\django\views\generic\base.py", line 104, in view
    return self.dispatch(request, *args, **kwargs)
           ^^^^^^^^^^^^^^^^^^^^^^^^^^^^^^^^^^^^^^^
  File "D:\zpj\python\ArtiOps\backend\venv\Lib\site-packages\django\utils\decorators.py", line 46, in _wrapper
    return bound_method(*args, **kwargs)
           ^^^^^^^^^^^^^^^^^^^^^^^^^^^^^
  File "D:\zpj\python\ArtiOps\backend\venv\Lib\site-packages\django\views\decorators\debug.py", line 92, in sensitive_post_parameters_wrapper
    return view(request, *args, **kwargs)
           ^^^^^^^^^^^^^^^^^^^^^^^^^^^^^^
  File "D:\zpj\python\ArtiOps\backend\venv\Lib\site-packages\django\utils\decorators.py", line 46, in _wrapper
    return bound_method(*args, **kwargs)
           ^^^^^^^^^^^^^^^^^^^^^^^^^^^^^
  File "D:\zpj\python\ArtiOps\backend\venv\Lib\site-packages\django\utils\decorators.py", line 134, in _wrapper_view
    response = view_func(request, *args, **kwargs)
               ^^^^^^^^^^^^^^^^^^^^^^^^^^^^^^^^^^^
  File "D:\zpj\python\ArtiOps\backend\venv\Lib\site-packages\django\utils\decorators.py", line 46, in _wrapper
    return bound_method(*args, **kwargs)
           ^^^^^^^^^^^^^^^^^^^^^^^^^^^^^
  File "D:\zpj\python\ArtiOps\backend\venv\Lib\site-packages\django\views\decorators\cache.py", line 62, in _wrapper_view_func
    response = view_func(request, *args, **kwargs)
               ^^^^^^^^^^^^^^^^^^^^^^^^^^^^^^^^^^^
  File "D:\zpj\python\ArtiOps\backend\venv\Lib\site-packages\django\contrib\auth\views.py", line 90, in dispatch
    return super().dispatch(request, *args, **kwargs)
           ^^^^^^^^^^^^^^^^^^^^^^^^^^^^^^^^^^^^^^^^^^
  File "D:\zpj\python\ArtiOps\backend\venv\Lib\site-packages\django\views\generic\base.py", line 143, in dispatch
    return handler(request, *args, **kwargs)
           ^^^^^^^^^^^^^^^^^^^^^^^^^^^^^^^^^
  File "D:\zpj\python\ArtiOps\backend\venv\Lib\site-packages\django\views\generic\edit.py", line 152, in post
    if form.is_valid():
       ^^^^^^^^^^^^^^^
  File "D:\zpj\python\ArtiOps\backend\venv\Lib\site-packages\django\forms\forms.py", line 201, in is_valid
    return self.is_bound and not self.errors
                                 ^^^^^^^^^^^
  File "D:\zpj\python\ArtiOps\backend\venv\Lib\site-packages\django\forms\forms.py", line 196, in errors
    self.full_clean()
  File "D:\zpj\python\ArtiOps\backend\venv\Lib\site-packages\django\forms\forms.py", line 434, in full_clean
    self._clean_form()
  File "D:\zpj\python\ArtiOps\backend\venv\Lib\site-packages\django\forms\forms.py", line 455, in _clean_form
    cleaned_data = self.clean()
                   ^^^^^^^^^^^^
  File "D:\zpj\python\ArtiOps\backend\venv\Lib\site-packages\django\contrib\auth\forms.py", line 242, in clean
    self.user_cache = authenticate(
                      ^^^^^^^^^^^^^
  File "D:\zpj\python\ArtiOps\backend\venv\Lib\site-packages\django\views\decorators\debug.py", line 42, in sensitive_variables_wrapper
    return func(*func_args, **func_kwargs)
           ^^^^^^^^^^^^^^^^^^^^^^^^^^^^^^^
  File "D:\zpj\python\ArtiOps\backend\venv\Lib\site-packages\django\contrib\auth\__init__.py", line 77, in authenticate
    user = backend.authenticate(request, **credentials)
           ^^^^^^^^^^^^^^^^^^^^^^^^^^^^^^^^^^^^^^^^^^^^
  File "D:\zpj\python\ArtiOps\backend\venv\Lib\site-packages\django\contrib\auth\backends.py", line 46, in authenticate
    user = UserModel._default_manager.get_by_natural_key(username)
           ^^^^^^^^^^^^^^^^^^^^^^^^^^^^^^^^^^^^^^^^^^^^^^^^^^^^^^^
  File "D:\zpj\python\ArtiOps\backend\venv\Lib\site-packages\django\contrib\auth\base_user.py", line 54, in get_by_natural_key
    return self.get(**{self.model.USERNAME_FIELD: username})
           ^^^^^^^^^^^^^^^^^^^^^^^^^^^^^^^^^^^^^^^^^^^^^^^^^
  File "D:\zpj\python\ArtiOps\backend\venv\Lib\site-packages\django\db\models\manager.py", line 87, in manager_method
    return getattr(self.get_queryset(), name)(*args, **kwargs)
           ^^^^^^^^^^^^^^^^^^^^^^^^^^^^^^^^^^^^^^^^^^^^^^^^^^^
  File "D:\zpj\python\ArtiOps\backend\venv\Lib\site-packages\django\db\models\query.py", line 633, in get
    num = len(clone)
          ^^^^^^^^^^
  File "D:\zpj\python\ArtiOps\backend\venv\Lib\site-packages\django\db\models\query.py", line 380, in __len__
    self._fetch_all()
  File "D:\zpj\python\ArtiOps\backend\venv\Lib\site-packages\django\db\models\query.py", line 1881, in _fetch_all
    self._result_cache = list(self._iterable_class(self))
                         ^^^^^^^^^^^^^^^^^^^^^^^^^^^^^^^^
  File "D:\zpj\python\ArtiOps\backend\venv\Lib\site-packages\django\db\models\query.py", line 91, in __iter__
    results = compiler.execute_sql(
              ^^^^^^^^^^^^^^^^^^^^^
  File "D:\zpj\python\ArtiOps\backend\venv\Lib\site-packages\django\db\models\sql\compiler.py", line 1560, in execute_sql
    cursor.execute(sql, params)
  File "D:\zpj\python\ArtiOps\backend\venv\Lib\site-packages\django\db\backends\utils.py", line 102, in execute
    return super().execute(sql, params)
           ^^^^^^^^^^^^^^^^^^^^^^^^^^^^
  File "D:\zpj\python\ArtiOps\backend\venv\Lib\site-packages\django\db\backends\utils.py", line 67, in execute
    return self._execute_with_wrappers(
           ^^^^^^^^^^^^^^^^^^^^^^^^^^^^
  File "D:\zpj\python\ArtiOps\backend\venv\Lib\site-packages\django\db\backends\utils.py", line 80, in _execute_with_wrappers
    return executor(sql, params, many, context)
           ^^^^^^^^^^^^^^^^^^^^^^^^^^^^^^^^^^^^
  File "D:\zpj\python\ArtiOps\backend\venv\Lib\site-packages\django\db\backends\utils.py", line 84, in _execute
    with self.db.wrap_database_errors:
  File "D:\zpj\python\ArtiOps\backend\venv\Lib\site-packages\django\db\utils.py", line 91, in __exit__
    raise dj_exc_value.with_traceback(traceback) from exc_value
  File "D:\zpj\python\ArtiOps\backend\venv\Lib\site-packages\django\db\backends\utils.py", line 89, in _execute
    return self.cursor.execute(sql, params)
           ^^^^^^^^^^^^^^^^^^^^^^^^^^^^^^^^
  File "D:\zpj\python\ArtiOps\backend\venv\Lib\site-packages\django\db\backends\sqlite3\base.py", line 328, in execute
    return super().execute(query, params)
           ^^^^^^^^^^^^^^^^^^^^^^^^^^^^^^
django.db.utils.OperationalError: no such table: users_user
ERROR 2025-06-17 18:02:11,453 basehttp 10840 17456 "POST /admin/login/?next=/admin/ HTTP/1.1" 500 254695
INFO 2025-06-17 18:16:04,171 autoreload 22560 10360 Watching for file changes with StatReloader
INFO 2025-06-17 18:16:20,045 basehttp 22560 18184 "GET /admin/login/? HTTP/1.1" 200 4182
INFO 2025-06-17 18:16:20,073 basehttp 22560 18184 "GET /static/admin/css/base.css HTTP/1.1" 304 0
INFO 2025-06-17 18:16:20,077 basehttp 22560 11940 "GET /static/admin/css/dark_mode.css HTTP/1.1" 304 0
INFO 2025-06-17 18:16:20,078 basehttp 22560 16456 "GET /static/admin/css/nav_sidebar.css HTTP/1.1" 304 0
INFO 2025-06-17 18:16:20,079 basehttp 22560 24884 "GET /static/admin/css/login.css HTTP/1.1" 304 0
INFO 2025-06-17 18:16:20,079 basehttp 22560 6940 "GET /static/admin/css/responsive.css HTTP/1.1" 304 0
INFO 2025-06-17 18:16:20,107 basehttp 22560 6940 "GET /static/admin/js/theme.js HTTP/1.1" 304 0
INFO 2025-06-17 18:16:20,107 basehttp 22560 24884 "GET /static/admin/js/nav_sidebar.js HTTP/1.1" 304 0
ERROR 2025-06-17 18:16:26,458 log 22560 24884 Internal Server Error: /admin/login/
Traceback (most recent call last):
  File "D:\zpj\python\ArtiOps\backend\venv\Lib\site-packages\django\db\backends\utils.py", line 89, in _execute
    return self.cursor.execute(sql, params)
           ^^^^^^^^^^^^^^^^^^^^^^^^^^^^^^^^
  File "D:\zpj\python\ArtiOps\backend\venv\Lib\site-packages\django\db\backends\sqlite3\base.py", line 328, in execute
    return super().execute(query, params)
           ^^^^^^^^^^^^^^^^^^^^^^^^^^^^^^
sqlite3.OperationalError: no such table: users_user

The above exception was the direct cause of the following exception:

Traceback (most recent call last):
  File "D:\zpj\python\ArtiOps\backend\venv\Lib\site-packages\django\core\handlers\exception.py", line 55, in inner
    response = get_response(request)
               ^^^^^^^^^^^^^^^^^^^^^
  File "D:\zpj\python\ArtiOps\backend\venv\Lib\site-packages\django\core\handlers\base.py", line 197, in _get_response
    response = wrapped_callback(request, *callback_args, **callback_kwargs)
               ^^^^^^^^^^^^^^^^^^^^^^^^^^^^^^^^^^^^^^^^^^^^^^^^^^^^^^^^^^^^
  File "D:\zpj\python\ArtiOps\backend\venv\Lib\site-packages\django\utils\decorators.py", line 46, in _wrapper
    return bound_method(*args, **kwargs)
           ^^^^^^^^^^^^^^^^^^^^^^^^^^^^^
  File "D:\zpj\python\ArtiOps\backend\venv\Lib\site-packages\django\views\decorators\cache.py", line 62, in _wrapper_view_func
    response = view_func(request, *args, **kwargs)
               ^^^^^^^^^^^^^^^^^^^^^^^^^^^^^^^^^^^
  File "D:\zpj\python\ArtiOps\backend\venv\Lib\site-packages\django\contrib\admin\sites.py", line 441, in login
    return LoginView.as_view(**defaults)(request)
           ^^^^^^^^^^^^^^^^^^^^^^^^^^^^^^^^^^^^^^
  File "D:\zpj\python\ArtiOps\backend\venv\Lib\site-packages\django\views\generic\base.py", line 104, in view
    return self.dispatch(request, *args, **kwargs)
           ^^^^^^^^^^^^^^^^^^^^^^^^^^^^^^^^^^^^^^^
  File "D:\zpj\python\ArtiOps\backend\venv\Lib\site-packages\django\utils\decorators.py", line 46, in _wrapper
    return bound_method(*args, **kwargs)
           ^^^^^^^^^^^^^^^^^^^^^^^^^^^^^
  File "D:\zpj\python\ArtiOps\backend\venv\Lib\site-packages\django\views\decorators\debug.py", line 92, in sensitive_post_parameters_wrapper
    return view(request, *args, **kwargs)
           ^^^^^^^^^^^^^^^^^^^^^^^^^^^^^^
  File "D:\zpj\python\ArtiOps\backend\venv\Lib\site-packages\django\utils\decorators.py", line 46, in _wrapper
    return bound_method(*args, **kwargs)
           ^^^^^^^^^^^^^^^^^^^^^^^^^^^^^
  File "D:\zpj\python\ArtiOps\backend\venv\Lib\site-packages\django\utils\decorators.py", line 134, in _wrapper_view
    response = view_func(request, *args, **kwargs)
               ^^^^^^^^^^^^^^^^^^^^^^^^^^^^^^^^^^^
  File "D:\zpj\python\ArtiOps\backend\venv\Lib\site-packages\django\utils\decorators.py", line 46, in _wrapper
    return bound_method(*args, **kwargs)
           ^^^^^^^^^^^^^^^^^^^^^^^^^^^^^
  File "D:\zpj\python\ArtiOps\backend\venv\Lib\site-packages\django\views\decorators\cache.py", line 62, in _wrapper_view_func
    response = view_func(request, *args, **kwargs)
               ^^^^^^^^^^^^^^^^^^^^^^^^^^^^^^^^^^^
  File "D:\zpj\python\ArtiOps\backend\venv\Lib\site-packages\django\contrib\auth\views.py", line 90, in dispatch
    return super().dispatch(request, *args, **kwargs)
           ^^^^^^^^^^^^^^^^^^^^^^^^^^^^^^^^^^^^^^^^^^
  File "D:\zpj\python\ArtiOps\backend\venv\Lib\site-packages\django\views\generic\base.py", line 143, in dispatch
    return handler(request, *args, **kwargs)
           ^^^^^^^^^^^^^^^^^^^^^^^^^^^^^^^^^
  File "D:\zpj\python\ArtiOps\backend\venv\Lib\site-packages\django\views\generic\edit.py", line 152, in post
    if form.is_valid():
       ^^^^^^^^^^^^^^^
  File "D:\zpj\python\ArtiOps\backend\venv\Lib\site-packages\django\forms\forms.py", line 201, in is_valid
    return self.is_bound and not self.errors
                                 ^^^^^^^^^^^
  File "D:\zpj\python\ArtiOps\backend\venv\Lib\site-packages\django\forms\forms.py", line 196, in errors
    self.full_clean()
  File "D:\zpj\python\ArtiOps\backend\venv\Lib\site-packages\django\forms\forms.py", line 434, in full_clean
    self._clean_form()
  File "D:\zpj\python\ArtiOps\backend\venv\Lib\site-packages\django\forms\forms.py", line 455, in _clean_form
    cleaned_data = self.clean()
                   ^^^^^^^^^^^^
  File "D:\zpj\python\ArtiOps\backend\venv\Lib\site-packages\django\contrib\auth\forms.py", line 242, in clean
    self.user_cache = authenticate(
                      ^^^^^^^^^^^^^
  File "D:\zpj\python\ArtiOps\backend\venv\Lib\site-packages\django\views\decorators\debug.py", line 42, in sensitive_variables_wrapper
    return func(*func_args, **func_kwargs)
           ^^^^^^^^^^^^^^^^^^^^^^^^^^^^^^^
  File "D:\zpj\python\ArtiOps\backend\venv\Lib\site-packages\django\contrib\auth\__init__.py", line 77, in authenticate
    user = backend.authenticate(request, **credentials)
           ^^^^^^^^^^^^^^^^^^^^^^^^^^^^^^^^^^^^^^^^^^^^
  File "D:\zpj\python\ArtiOps\backend\venv\Lib\site-packages\django\contrib\auth\backends.py", line 46, in authenticate
    user = UserModel._default_manager.get_by_natural_key(username)
           ^^^^^^^^^^^^^^^^^^^^^^^^^^^^^^^^^^^^^^^^^^^^^^^^^^^^^^^
  File "D:\zpj\python\ArtiOps\backend\venv\Lib\site-packages\django\contrib\auth\base_user.py", line 54, in get_by_natural_key
    return self.get(**{self.model.USERNAME_FIELD: username})
           ^^^^^^^^^^^^^^^^^^^^^^^^^^^^^^^^^^^^^^^^^^^^^^^^^
  File "D:\zpj\python\ArtiOps\backend\venv\Lib\site-packages\django\db\models\manager.py", line 87, in manager_method
    return getattr(self.get_queryset(), name)(*args, **kwargs)
           ^^^^^^^^^^^^^^^^^^^^^^^^^^^^^^^^^^^^^^^^^^^^^^^^^^^
  File "D:\zpj\python\ArtiOps\backend\venv\Lib\site-packages\django\db\models\query.py", line 633, in get
    num = len(clone)
          ^^^^^^^^^^
  File "D:\zpj\python\ArtiOps\backend\venv\Lib\site-packages\django\db\models\query.py", line 380, in __len__
    self._fetch_all()
  File "D:\zpj\python\ArtiOps\backend\venv\Lib\site-packages\django\db\models\query.py", line 1881, in _fetch_all
    self._result_cache = list(self._iterable_class(self))
                         ^^^^^^^^^^^^^^^^^^^^^^^^^^^^^^^^
  File "D:\zpj\python\ArtiOps\backend\venv\Lib\site-packages\django\db\models\query.py", line 91, in __iter__
    results = compiler.execute_sql(
              ^^^^^^^^^^^^^^^^^^^^^
  File "D:\zpj\python\ArtiOps\backend\venv\Lib\site-packages\django\db\models\sql\compiler.py", line 1560, in execute_sql
    cursor.execute(sql, params)
  File "D:\zpj\python\ArtiOps\backend\venv\Lib\site-packages\django\db\backends\utils.py", line 102, in execute
    return super().execute(sql, params)
           ^^^^^^^^^^^^^^^^^^^^^^^^^^^^
  File "D:\zpj\python\ArtiOps\backend\venv\Lib\site-packages\django\db\backends\utils.py", line 67, in execute
    return self._execute_with_wrappers(
           ^^^^^^^^^^^^^^^^^^^^^^^^^^^^
  File "D:\zpj\python\ArtiOps\backend\venv\Lib\site-packages\django\db\backends\utils.py", line 80, in _execute_with_wrappers
    return executor(sql, params, many, context)
           ^^^^^^^^^^^^^^^^^^^^^^^^^^^^^^^^^^^^
  File "D:\zpj\python\ArtiOps\backend\venv\Lib\site-packages\django\db\backends\utils.py", line 84, in _execute
    with self.db.wrap_database_errors:
  File "D:\zpj\python\ArtiOps\backend\venv\Lib\site-packages\django\db\utils.py", line 91, in __exit__
    raise dj_exc_value.with_traceback(traceback) from exc_value
  File "D:\zpj\python\ArtiOps\backend\venv\Lib\site-packages\django\db\backends\utils.py", line 89, in _execute
    return self.cursor.execute(sql, params)
           ^^^^^^^^^^^^^^^^^^^^^^^^^^^^^^^^
  File "D:\zpj\python\ArtiOps\backend\venv\Lib\site-packages\django\db\backends\sqlite3\base.py", line 328, in execute
    return super().execute(query, params)
           ^^^^^^^^^^^^^^^^^^^^^^^^^^^^^^
django.db.utils.OperationalError: no such table: users_user
ERROR 2025-06-17 18:16:26,467 basehttp 22560 24884 "POST /admin/login/ HTTP/1.1" 500 254093
INFO 2025-06-17 18:18:32,540 basehttp 22560 24884 "GET /admin/login/? HTTP/1.1" 200 4182
ERROR 2025-06-17 18:18:36,170 log 22560 24884 Internal Server Error: /admin/login/
Traceback (most recent call last):
  File "D:\zpj\python\ArtiOps\backend\venv\Lib\site-packages\django\db\backends\utils.py", line 89, in _execute
    return self.cursor.execute(sql, params)
           ^^^^^^^^^^^^^^^^^^^^^^^^^^^^^^^^
  File "D:\zpj\python\ArtiOps\backend\venv\Lib\site-packages\django\db\backends\sqlite3\base.py", line 328, in execute
    return super().execute(query, params)
           ^^^^^^^^^^^^^^^^^^^^^^^^^^^^^^
sqlite3.OperationalError: no such table: users_user

The above exception was the direct cause of the following exception:

Traceback (most recent call last):
  File "D:\zpj\python\ArtiOps\backend\venv\Lib\site-packages\django\core\handlers\exception.py", line 55, in inner
    response = get_response(request)
               ^^^^^^^^^^^^^^^^^^^^^
  File "D:\zpj\python\ArtiOps\backend\venv\Lib\site-packages\django\core\handlers\base.py", line 197, in _get_response
    response = wrapped_callback(request, *callback_args, **callback_kwargs)
               ^^^^^^^^^^^^^^^^^^^^^^^^^^^^^^^^^^^^^^^^^^^^^^^^^^^^^^^^^^^^
  File "D:\zpj\python\ArtiOps\backend\venv\Lib\site-packages\django\utils\decorators.py", line 46, in _wrapper
    return bound_method(*args, **kwargs)
           ^^^^^^^^^^^^^^^^^^^^^^^^^^^^^
  File "D:\zpj\python\ArtiOps\backend\venv\Lib\site-packages\django\views\decorators\cache.py", line 62, in _wrapper_view_func
    response = view_func(request, *args, **kwargs)
               ^^^^^^^^^^^^^^^^^^^^^^^^^^^^^^^^^^^
  File "D:\zpj\python\ArtiOps\backend\venv\Lib\site-packages\django\contrib\admin\sites.py", line 441, in login
    return LoginView.as_view(**defaults)(request)
           ^^^^^^^^^^^^^^^^^^^^^^^^^^^^^^^^^^^^^^
  File "D:\zpj\python\ArtiOps\backend\venv\Lib\site-packages\django\views\generic\base.py", line 104, in view
    return self.dispatch(request, *args, **kwargs)
           ^^^^^^^^^^^^^^^^^^^^^^^^^^^^^^^^^^^^^^^
  File "D:\zpj\python\ArtiOps\backend\venv\Lib\site-packages\django\utils\decorators.py", line 46, in _wrapper
    return bound_method(*args, **kwargs)
           ^^^^^^^^^^^^^^^^^^^^^^^^^^^^^
  File "D:\zpj\python\ArtiOps\backend\venv\Lib\site-packages\django\views\decorators\debug.py", line 92, in sensitive_post_parameters_wrapper
    return view(request, *args, **kwargs)
           ^^^^^^^^^^^^^^^^^^^^^^^^^^^^^^
  File "D:\zpj\python\ArtiOps\backend\venv\Lib\site-packages\django\utils\decorators.py", line 46, in _wrapper
    return bound_method(*args, **kwargs)
           ^^^^^^^^^^^^^^^^^^^^^^^^^^^^^
  File "D:\zpj\python\ArtiOps\backend\venv\Lib\site-packages\django\utils\decorators.py", line 134, in _wrapper_view
    response = view_func(request, *args, **kwargs)
               ^^^^^^^^^^^^^^^^^^^^^^^^^^^^^^^^^^^
  File "D:\zpj\python\ArtiOps\backend\venv\Lib\site-packages\django\utils\decorators.py", line 46, in _wrapper
    return bound_method(*args, **kwargs)
           ^^^^^^^^^^^^^^^^^^^^^^^^^^^^^
  File "D:\zpj\python\ArtiOps\backend\venv\Lib\site-packages\django\views\decorators\cache.py", line 62, in _wrapper_view_func
    response = view_func(request, *args, **kwargs)
               ^^^^^^^^^^^^^^^^^^^^^^^^^^^^^^^^^^^
  File "D:\zpj\python\ArtiOps\backend\venv\Lib\site-packages\django\contrib\auth\views.py", line 90, in dispatch
    return super().dispatch(request, *args, **kwargs)
           ^^^^^^^^^^^^^^^^^^^^^^^^^^^^^^^^^^^^^^^^^^
  File "D:\zpj\python\ArtiOps\backend\venv\Lib\site-packages\django\views\generic\base.py", line 143, in dispatch
    return handler(request, *args, **kwargs)
           ^^^^^^^^^^^^^^^^^^^^^^^^^^^^^^^^^
  File "D:\zpj\python\ArtiOps\backend\venv\Lib\site-packages\django\views\generic\edit.py", line 152, in post
    if form.is_valid():
       ^^^^^^^^^^^^^^^
  File "D:\zpj\python\ArtiOps\backend\venv\Lib\site-packages\django\forms\forms.py", line 201, in is_valid
    return self.is_bound and not self.errors
                                 ^^^^^^^^^^^
  File "D:\zpj\python\ArtiOps\backend\venv\Lib\site-packages\django\forms\forms.py", line 196, in errors
    self.full_clean()
  File "D:\zpj\python\ArtiOps\backend\venv\Lib\site-packages\django\forms\forms.py", line 434, in full_clean
    self._clean_form()
  File "D:\zpj\python\ArtiOps\backend\venv\Lib\site-packages\django\forms\forms.py", line 455, in _clean_form
    cleaned_data = self.clean()
                   ^^^^^^^^^^^^
  File "D:\zpj\python\ArtiOps\backend\venv\Lib\site-packages\django\contrib\auth\forms.py", line 242, in clean
    self.user_cache = authenticate(
                      ^^^^^^^^^^^^^
  File "D:\zpj\python\ArtiOps\backend\venv\Lib\site-packages\django\views\decorators\debug.py", line 42, in sensitive_variables_wrapper
    return func(*func_args, **func_kwargs)
           ^^^^^^^^^^^^^^^^^^^^^^^^^^^^^^^
  File "D:\zpj\python\ArtiOps\backend\venv\Lib\site-packages\django\contrib\auth\__init__.py", line 77, in authenticate
    user = backend.authenticate(request, **credentials)
           ^^^^^^^^^^^^^^^^^^^^^^^^^^^^^^^^^^^^^^^^^^^^
  File "D:\zpj\python\ArtiOps\backend\venv\Lib\site-packages\django\contrib\auth\backends.py", line 46, in authenticate
    user = UserModel._default_manager.get_by_natural_key(username)
           ^^^^^^^^^^^^^^^^^^^^^^^^^^^^^^^^^^^^^^^^^^^^^^^^^^^^^^^
  File "D:\zpj\python\ArtiOps\backend\venv\Lib\site-packages\django\contrib\auth\base_user.py", line 54, in get_by_natural_key
    return self.get(**{self.model.USERNAME_FIELD: username})
           ^^^^^^^^^^^^^^^^^^^^^^^^^^^^^^^^^^^^^^^^^^^^^^^^^
  File "D:\zpj\python\ArtiOps\backend\venv\Lib\site-packages\django\db\models\manager.py", line 87, in manager_method
    return getattr(self.get_queryset(), name)(*args, **kwargs)
           ^^^^^^^^^^^^^^^^^^^^^^^^^^^^^^^^^^^^^^^^^^^^^^^^^^^
  File "D:\zpj\python\ArtiOps\backend\venv\Lib\site-packages\django\db\models\query.py", line 633, in get
    num = len(clone)
          ^^^^^^^^^^
  File "D:\zpj\python\ArtiOps\backend\venv\Lib\site-packages\django\db\models\query.py", line 380, in __len__
    self._fetch_all()
  File "D:\zpj\python\ArtiOps\backend\venv\Lib\site-packages\django\db\models\query.py", line 1881, in _fetch_all
    self._result_cache = list(self._iterable_class(self))
                         ^^^^^^^^^^^^^^^^^^^^^^^^^^^^^^^^
  File "D:\zpj\python\ArtiOps\backend\venv\Lib\site-packages\django\db\models\query.py", line 91, in __iter__
    results = compiler.execute_sql(
              ^^^^^^^^^^^^^^^^^^^^^
  File "D:\zpj\python\ArtiOps\backend\venv\Lib\site-packages\django\db\models\sql\compiler.py", line 1560, in execute_sql
    cursor.execute(sql, params)
  File "D:\zpj\python\ArtiOps\backend\venv\Lib\site-packages\django\db\backends\utils.py", line 102, in execute
    return super().execute(sql, params)
           ^^^^^^^^^^^^^^^^^^^^^^^^^^^^
  File "D:\zpj\python\ArtiOps\backend\venv\Lib\site-packages\django\db\backends\utils.py", line 67, in execute
    return self._execute_with_wrappers(
           ^^^^^^^^^^^^^^^^^^^^^^^^^^^^
  File "D:\zpj\python\ArtiOps\backend\venv\Lib\site-packages\django\db\backends\utils.py", line 80, in _execute_with_wrappers
    return executor(sql, params, many, context)
           ^^^^^^^^^^^^^^^^^^^^^^^^^^^^^^^^^^^^
  File "D:\zpj\python\ArtiOps\backend\venv\Lib\site-packages\django\db\backends\utils.py", line 84, in _execute
    with self.db.wrap_database_errors:
  File "D:\zpj\python\ArtiOps\backend\venv\Lib\site-packages\django\db\utils.py", line 91, in __exit__
    raise dj_exc_value.with_traceback(traceback) from exc_value
  File "D:\zpj\python\ArtiOps\backend\venv\Lib\site-packages\django\db\backends\utils.py", line 89, in _execute
    return self.cursor.execute(sql, params)
           ^^^^^^^^^^^^^^^^^^^^^^^^^^^^^^^^
  File "D:\zpj\python\ArtiOps\backend\venv\Lib\site-packages\django\db\backends\sqlite3\base.py", line 328, in execute
    return super().execute(query, params)
           ^^^^^^^^^^^^^^^^^^^^^^^^^^^^^^
django.db.utils.OperationalError: no such table: users_user
ERROR 2025-06-17 18:18:36,178 basehttp 22560 24884 "POST /admin/login/ HTTP/1.1" 500 254089
ERROR 2025-06-17 18:18:41,940 log 22560 24884 Internal Server Error: /admin/login/
Traceback (most recent call last):
  File "D:\zpj\python\ArtiOps\backend\venv\Lib\site-packages\django\db\backends\utils.py", line 89, in _execute
    return self.cursor.execute(sql, params)
           ^^^^^^^^^^^^^^^^^^^^^^^^^^^^^^^^
  File "D:\zpj\python\ArtiOps\backend\venv\Lib\site-packages\django\db\backends\sqlite3\base.py", line 328, in execute
    return super().execute(query, params)
           ^^^^^^^^^^^^^^^^^^^^^^^^^^^^^^
sqlite3.OperationalError: no such table: users_user

The above exception was the direct cause of the following exception:

Traceback (most recent call last):
  File "D:\zpj\python\ArtiOps\backend\venv\Lib\site-packages\django\core\handlers\exception.py", line 55, in inner
    response = get_response(request)
               ^^^^^^^^^^^^^^^^^^^^^
  File "D:\zpj\python\ArtiOps\backend\venv\Lib\site-packages\django\core\handlers\base.py", line 197, in _get_response
    response = wrapped_callback(request, *callback_args, **callback_kwargs)
               ^^^^^^^^^^^^^^^^^^^^^^^^^^^^^^^^^^^^^^^^^^^^^^^^^^^^^^^^^^^^
  File "D:\zpj\python\ArtiOps\backend\venv\Lib\site-packages\django\utils\decorators.py", line 46, in _wrapper
    return bound_method(*args, **kwargs)
           ^^^^^^^^^^^^^^^^^^^^^^^^^^^^^
  File "D:\zpj\python\ArtiOps\backend\venv\Lib\site-packages\django\views\decorators\cache.py", line 62, in _wrapper_view_func
    response = view_func(request, *args, **kwargs)
               ^^^^^^^^^^^^^^^^^^^^^^^^^^^^^^^^^^^
  File "D:\zpj\python\ArtiOps\backend\venv\Lib\site-packages\django\contrib\admin\sites.py", line 441, in login
    return LoginView.as_view(**defaults)(request)
           ^^^^^^^^^^^^^^^^^^^^^^^^^^^^^^^^^^^^^^
  File "D:\zpj\python\ArtiOps\backend\venv\Lib\site-packages\django\views\generic\base.py", line 104, in view
    return self.dispatch(request, *args, **kwargs)
           ^^^^^^^^^^^^^^^^^^^^^^^^^^^^^^^^^^^^^^^
  File "D:\zpj\python\ArtiOps\backend\venv\Lib\site-packages\django\utils\decorators.py", line 46, in _wrapper
    return bound_method(*args, **kwargs)
           ^^^^^^^^^^^^^^^^^^^^^^^^^^^^^
  File "D:\zpj\python\ArtiOps\backend\venv\Lib\site-packages\django\views\decorators\debug.py", line 92, in sensitive_post_parameters_wrapper
    return view(request, *args, **kwargs)
           ^^^^^^^^^^^^^^^^^^^^^^^^^^^^^^
  File "D:\zpj\python\ArtiOps\backend\venv\Lib\site-packages\django\utils\decorators.py", line 46, in _wrapper
    return bound_method(*args, **kwargs)
           ^^^^^^^^^^^^^^^^^^^^^^^^^^^^^
  File "D:\zpj\python\ArtiOps\backend\venv\Lib\site-packages\django\utils\decorators.py", line 134, in _wrapper_view
    response = view_func(request, *args, **kwargs)
               ^^^^^^^^^^^^^^^^^^^^^^^^^^^^^^^^^^^
  File "D:\zpj\python\ArtiOps\backend\venv\Lib\site-packages\django\utils\decorators.py", line 46, in _wrapper
    return bound_method(*args, **kwargs)
           ^^^^^^^^^^^^^^^^^^^^^^^^^^^^^
  File "D:\zpj\python\ArtiOps\backend\venv\Lib\site-packages\django\views\decorators\cache.py", line 62, in _wrapper_view_func
    response = view_func(request, *args, **kwargs)
               ^^^^^^^^^^^^^^^^^^^^^^^^^^^^^^^^^^^
  File "D:\zpj\python\ArtiOps\backend\venv\Lib\site-packages\django\contrib\auth\views.py", line 90, in dispatch
    return super().dispatch(request, *args, **kwargs)
           ^^^^^^^^^^^^^^^^^^^^^^^^^^^^^^^^^^^^^^^^^^
  File "D:\zpj\python\ArtiOps\backend\venv\Lib\site-packages\django\views\generic\base.py", line 143, in dispatch
    return handler(request, *args, **kwargs)
           ^^^^^^^^^^^^^^^^^^^^^^^^^^^^^^^^^
  File "D:\zpj\python\ArtiOps\backend\venv\Lib\site-packages\django\views\generic\edit.py", line 152, in post
    if form.is_valid():
       ^^^^^^^^^^^^^^^
  File "D:\zpj\python\ArtiOps\backend\venv\Lib\site-packages\django\forms\forms.py", line 201, in is_valid
    return self.is_bound and not self.errors
                                 ^^^^^^^^^^^
  File "D:\zpj\python\ArtiOps\backend\venv\Lib\site-packages\django\forms\forms.py", line 196, in errors
    self.full_clean()
  File "D:\zpj\python\ArtiOps\backend\venv\Lib\site-packages\django\forms\forms.py", line 434, in full_clean
    self._clean_form()
  File "D:\zpj\python\ArtiOps\backend\venv\Lib\site-packages\django\forms\forms.py", line 455, in _clean_form
    cleaned_data = self.clean()
                   ^^^^^^^^^^^^
  File "D:\zpj\python\ArtiOps\backend\venv\Lib\site-packages\django\contrib\auth\forms.py", line 242, in clean
    self.user_cache = authenticate(
                      ^^^^^^^^^^^^^
  File "D:\zpj\python\ArtiOps\backend\venv\Lib\site-packages\django\views\decorators\debug.py", line 42, in sensitive_variables_wrapper
    return func(*func_args, **func_kwargs)
           ^^^^^^^^^^^^^^^^^^^^^^^^^^^^^^^
  File "D:\zpj\python\ArtiOps\backend\venv\Lib\site-packages\django\contrib\auth\__init__.py", line 77, in authenticate
    user = backend.authenticate(request, **credentials)
           ^^^^^^^^^^^^^^^^^^^^^^^^^^^^^^^^^^^^^^^^^^^^
  File "D:\zpj\python\ArtiOps\backend\venv\Lib\site-packages\django\contrib\auth\backends.py", line 46, in authenticate
    user = UserModel._default_manager.get_by_natural_key(username)
           ^^^^^^^^^^^^^^^^^^^^^^^^^^^^^^^^^^^^^^^^^^^^^^^^^^^^^^^
  File "D:\zpj\python\ArtiOps\backend\venv\Lib\site-packages\django\contrib\auth\base_user.py", line 54, in get_by_natural_key
    return self.get(**{self.model.USERNAME_FIELD: username})
           ^^^^^^^^^^^^^^^^^^^^^^^^^^^^^^^^^^^^^^^^^^^^^^^^^
  File "D:\zpj\python\ArtiOps\backend\venv\Lib\site-packages\django\db\models\manager.py", line 87, in manager_method
    return getattr(self.get_queryset(), name)(*args, **kwargs)
           ^^^^^^^^^^^^^^^^^^^^^^^^^^^^^^^^^^^^^^^^^^^^^^^^^^^
  File "D:\zpj\python\ArtiOps\backend\venv\Lib\site-packages\django\db\models\query.py", line 633, in get
    num = len(clone)
          ^^^^^^^^^^
  File "D:\zpj\python\ArtiOps\backend\venv\Lib\site-packages\django\db\models\query.py", line 380, in __len__
    self._fetch_all()
  File "D:\zpj\python\ArtiOps\backend\venv\Lib\site-packages\django\db\models\query.py", line 1881, in _fetch_all
    self._result_cache = list(self._iterable_class(self))
                         ^^^^^^^^^^^^^^^^^^^^^^^^^^^^^^^^
  File "D:\zpj\python\ArtiOps\backend\venv\Lib\site-packages\django\db\models\query.py", line 91, in __iter__
    results = compiler.execute_sql(
              ^^^^^^^^^^^^^^^^^^^^^
  File "D:\zpj\python\ArtiOps\backend\venv\Lib\site-packages\django\db\models\sql\compiler.py", line 1560, in execute_sql
    cursor.execute(sql, params)
  File "D:\zpj\python\ArtiOps\backend\venv\Lib\site-packages\django\db\backends\utils.py", line 102, in execute
    return super().execute(sql, params)
           ^^^^^^^^^^^^^^^^^^^^^^^^^^^^
  File "D:\zpj\python\ArtiOps\backend\venv\Lib\site-packages\django\db\backends\utils.py", line 67, in execute
    return self._execute_with_wrappers(
           ^^^^^^^^^^^^^^^^^^^^^^^^^^^^
  File "D:\zpj\python\ArtiOps\backend\venv\Lib\site-packages\django\db\backends\utils.py", line 80, in _execute_with_wrappers
    return executor(sql, params, many, context)
           ^^^^^^^^^^^^^^^^^^^^^^^^^^^^^^^^^^^^
  File "D:\zpj\python\ArtiOps\backend\venv\Lib\site-packages\django\db\backends\utils.py", line 84, in _execute
    with self.db.wrap_database_errors:
  File "D:\zpj\python\ArtiOps\backend\venv\Lib\site-packages\django\db\utils.py", line 91, in __exit__
    raise dj_exc_value.with_traceback(traceback) from exc_value
  File "D:\zpj\python\ArtiOps\backend\venv\Lib\site-packages\django\db\backends\utils.py", line 89, in _execute
    return self.cursor.execute(sql, params)
           ^^^^^^^^^^^^^^^^^^^^^^^^^^^^^^^^
  File "D:\zpj\python\ArtiOps\backend\venv\Lib\site-packages\django\db\backends\sqlite3\base.py", line 328, in execute
    return super().execute(query, params)
           ^^^^^^^^^^^^^^^^^^^^^^^^^^^^^^
django.db.utils.OperationalError: no such table: users_user
ERROR 2025-06-17 18:18:41,948 basehttp 22560 24884 "POST /admin/login/ HTTP/1.1" 500 254217
WARNING 2025-06-17 18:18:42,197 log 22560 24884 Not Found: /favicon.ico
WARNING 2025-06-17 18:18:42,198 basehttp 22560 24884 "GET /favicon.ico HTTP/1.1" 404 2604
INFO 2025-06-17 18:19:03,649 autoreload 27368 22448 Watching for file changes with StatReloader
INFO 2025-06-17 18:19:16,844 basehttp 27368 15160 "GET /admin/login/? HTTP/1.1" 200 4182
ERROR 2025-06-17 18:19:22,936 log 27368 15160 Internal Server Error: /admin/login/
Traceback (most recent call last):
  File "D:\zpj\python\ArtiOps\backend\venv\Lib\site-packages\django\db\backends\utils.py", line 89, in _execute
    return self.cursor.execute(sql, params)
           ^^^^^^^^^^^^^^^^^^^^^^^^^^^^^^^^
  File "D:\zpj\python\ArtiOps\backend\venv\Lib\site-packages\django\db\backends\sqlite3\base.py", line 328, in execute
    return super().execute(query, params)
           ^^^^^^^^^^^^^^^^^^^^^^^^^^^^^^
sqlite3.OperationalError: no such table: users_user

The above exception was the direct cause of the following exception:

Traceback (most recent call last):
  File "D:\zpj\python\ArtiOps\backend\venv\Lib\site-packages\django\core\handlers\exception.py", line 55, in inner
    response = get_response(request)
               ^^^^^^^^^^^^^^^^^^^^^
  File "D:\zpj\python\ArtiOps\backend\venv\Lib\site-packages\django\core\handlers\base.py", line 197, in _get_response
    response = wrapped_callback(request, *callback_args, **callback_kwargs)
               ^^^^^^^^^^^^^^^^^^^^^^^^^^^^^^^^^^^^^^^^^^^^^^^^^^^^^^^^^^^^
  File "D:\zpj\python\ArtiOps\backend\venv\Lib\site-packages\django\utils\decorators.py", line 46, in _wrapper
    return bound_method(*args, **kwargs)
           ^^^^^^^^^^^^^^^^^^^^^^^^^^^^^
  File "D:\zpj\python\ArtiOps\backend\venv\Lib\site-packages\django\views\decorators\cache.py", line 62, in _wrapper_view_func
    response = view_func(request, *args, **kwargs)
               ^^^^^^^^^^^^^^^^^^^^^^^^^^^^^^^^^^^
  File "D:\zpj\python\ArtiOps\backend\venv\Lib\site-packages\django\contrib\admin\sites.py", line 441, in login
    return LoginView.as_view(**defaults)(request)
           ^^^^^^^^^^^^^^^^^^^^^^^^^^^^^^^^^^^^^^
  File "D:\zpj\python\ArtiOps\backend\venv\Lib\site-packages\django\views\generic\base.py", line 104, in view
    return self.dispatch(request, *args, **kwargs)
           ^^^^^^^^^^^^^^^^^^^^^^^^^^^^^^^^^^^^^^^
  File "D:\zpj\python\ArtiOps\backend\venv\Lib\site-packages\django\utils\decorators.py", line 46, in _wrapper
    return bound_method(*args, **kwargs)
           ^^^^^^^^^^^^^^^^^^^^^^^^^^^^^
  File "D:\zpj\python\ArtiOps\backend\venv\Lib\site-packages\django\views\decorators\debug.py", line 92, in sensitive_post_parameters_wrapper
    return view(request, *args, **kwargs)
           ^^^^^^^^^^^^^^^^^^^^^^^^^^^^^^
  File "D:\zpj\python\ArtiOps\backend\venv\Lib\site-packages\django\utils\decorators.py", line 46, in _wrapper
    return bound_method(*args, **kwargs)
           ^^^^^^^^^^^^^^^^^^^^^^^^^^^^^
  File "D:\zpj\python\ArtiOps\backend\venv\Lib\site-packages\django\utils\decorators.py", line 134, in _wrapper_view
    response = view_func(request, *args, **kwargs)
               ^^^^^^^^^^^^^^^^^^^^^^^^^^^^^^^^^^^
  File "D:\zpj\python\ArtiOps\backend\venv\Lib\site-packages\django\utils\decorators.py", line 46, in _wrapper
    return bound_method(*args, **kwargs)
           ^^^^^^^^^^^^^^^^^^^^^^^^^^^^^
  File "D:\zpj\python\ArtiOps\backend\venv\Lib\site-packages\django\views\decorators\cache.py", line 62, in _wrapper_view_func
    response = view_func(request, *args, **kwargs)
               ^^^^^^^^^^^^^^^^^^^^^^^^^^^^^^^^^^^
  File "D:\zpj\python\ArtiOps\backend\venv\Lib\site-packages\django\contrib\auth\views.py", line 90, in dispatch
    return super().dispatch(request, *args, **kwargs)
           ^^^^^^^^^^^^^^^^^^^^^^^^^^^^^^^^^^^^^^^^^^
  File "D:\zpj\python\ArtiOps\backend\venv\Lib\site-packages\django\views\generic\base.py", line 143, in dispatch
    return handler(request, *args, **kwargs)
           ^^^^^^^^^^^^^^^^^^^^^^^^^^^^^^^^^
  File "D:\zpj\python\ArtiOps\backend\venv\Lib\site-packages\django\views\generic\edit.py", line 152, in post
    if form.is_valid():
       ^^^^^^^^^^^^^^^
  File "D:\zpj\python\ArtiOps\backend\venv\Lib\site-packages\django\forms\forms.py", line 201, in is_valid
    return self.is_bound and not self.errors
                                 ^^^^^^^^^^^
  File "D:\zpj\python\ArtiOps\backend\venv\Lib\site-packages\django\forms\forms.py", line 196, in errors
    self.full_clean()
  File "D:\zpj\python\ArtiOps\backend\venv\Lib\site-packages\django\forms\forms.py", line 434, in full_clean
    self._clean_form()
  File "D:\zpj\python\ArtiOps\backend\venv\Lib\site-packages\django\forms\forms.py", line 455, in _clean_form
    cleaned_data = self.clean()
                   ^^^^^^^^^^^^
  File "D:\zpj\python\ArtiOps\backend\venv\Lib\site-packages\django\contrib\auth\forms.py", line 242, in clean
    self.user_cache = authenticate(
                      ^^^^^^^^^^^^^
  File "D:\zpj\python\ArtiOps\backend\venv\Lib\site-packages\django\views\decorators\debug.py", line 42, in sensitive_variables_wrapper
    return func(*func_args, **func_kwargs)
           ^^^^^^^^^^^^^^^^^^^^^^^^^^^^^^^
  File "D:\zpj\python\ArtiOps\backend\venv\Lib\site-packages\django\contrib\auth\__init__.py", line 77, in authenticate
    user = backend.authenticate(request, **credentials)
           ^^^^^^^^^^^^^^^^^^^^^^^^^^^^^^^^^^^^^^^^^^^^
  File "D:\zpj\python\ArtiOps\backend\venv\Lib\site-packages\django\contrib\auth\backends.py", line 46, in authenticate
    user = UserModel._default_manager.get_by_natural_key(username)
           ^^^^^^^^^^^^^^^^^^^^^^^^^^^^^^^^^^^^^^^^^^^^^^^^^^^^^^^
  File "D:\zpj\python\ArtiOps\backend\venv\Lib\site-packages\django\contrib\auth\base_user.py", line 54, in get_by_natural_key
    return self.get(**{self.model.USERNAME_FIELD: username})
           ^^^^^^^^^^^^^^^^^^^^^^^^^^^^^^^^^^^^^^^^^^^^^^^^^
  File "D:\zpj\python\ArtiOps\backend\venv\Lib\site-packages\django\db\models\manager.py", line 87, in manager_method
    return getattr(self.get_queryset(), name)(*args, **kwargs)
           ^^^^^^^^^^^^^^^^^^^^^^^^^^^^^^^^^^^^^^^^^^^^^^^^^^^
  File "D:\zpj\python\ArtiOps\backend\venv\Lib\site-packages\django\db\models\query.py", line 633, in get
    num = len(clone)
          ^^^^^^^^^^
  File "D:\zpj\python\ArtiOps\backend\venv\Lib\site-packages\django\db\models\query.py", line 380, in __len__
    self._fetch_all()
  File "D:\zpj\python\ArtiOps\backend\venv\Lib\site-packages\django\db\models\query.py", line 1881, in _fetch_all
    self._result_cache = list(self._iterable_class(self))
                         ^^^^^^^^^^^^^^^^^^^^^^^^^^^^^^^^
  File "D:\zpj\python\ArtiOps\backend\venv\Lib\site-packages\django\db\models\query.py", line 91, in __iter__
    results = compiler.execute_sql(
              ^^^^^^^^^^^^^^^^^^^^^
  File "D:\zpj\python\ArtiOps\backend\venv\Lib\site-packages\django\db\models\sql\compiler.py", line 1560, in execute_sql
    cursor.execute(sql, params)
  File "D:\zpj\python\ArtiOps\backend\venv\Lib\site-packages\django\db\backends\utils.py", line 102, in execute
    return super().execute(sql, params)
           ^^^^^^^^^^^^^^^^^^^^^^^^^^^^
  File "D:\zpj\python\ArtiOps\backend\venv\Lib\site-packages\django\db\backends\utils.py", line 67, in execute
    return self._execute_with_wrappers(
           ^^^^^^^^^^^^^^^^^^^^^^^^^^^^
  File "D:\zpj\python\ArtiOps\backend\venv\Lib\site-packages\django\db\backends\utils.py", line 80, in _execute_with_wrappers
    return executor(sql, params, many, context)
           ^^^^^^^^^^^^^^^^^^^^^^^^^^^^^^^^^^^^
  File "D:\zpj\python\ArtiOps\backend\venv\Lib\site-packages\django\db\backends\utils.py", line 84, in _execute
    with self.db.wrap_database_errors:
  File "D:\zpj\python\ArtiOps\backend\venv\Lib\site-packages\django\db\utils.py", line 91, in __exit__
    raise dj_exc_value.with_traceback(traceback) from exc_value
  File "D:\zpj\python\ArtiOps\backend\venv\Lib\site-packages\django\db\backends\utils.py", line 89, in _execute
    return self.cursor.execute(sql, params)
           ^^^^^^^^^^^^^^^^^^^^^^^^^^^^^^^^
  File "D:\zpj\python\ArtiOps\backend\venv\Lib\site-packages\django\db\backends\sqlite3\base.py", line 328, in execute
    return super().execute(query, params)
           ^^^^^^^^^^^^^^^^^^^^^^^^^^^^^^
django.db.utils.OperationalError: no such table: users_user
ERROR 2025-06-17 18:19:22,947 basehttp 27368 15160 "POST /admin/login/ HTTP/1.1" 500 254089
INFO 2025-06-17 18:20:25,613 autoreload 29656 3504 Watching for file changes with StatReloader
